<?xml version="1.0" ?>
<!-- =================================================================================== -->
<!-- |    This document was autogenerated by xacro from ./simenv.xacro                 | -->
<!-- |    EDITING THIS FILE BY HAND IS NOT RECOMMENDED                                 | -->
<!-- =================================================================================== -->
<robot name="lemons">
    <link name="arm0" />
    <joint name="joint_fix" type="fixed">
        <origin xyz="0 0 0" />
        <parent link="arm0" />
        <child link="base_link" />
    </joint>
    <link name="base_link">
        <collision>
            <origin rpy="0 0 0" xyz="0 0 0.2" />
            <geometry>
                <cylinder length="0.4" radius="0.1" />
            </geometry>
        </collision>
        <visual>
            <origin rpy="0 0 0" xyz="0 0 0.2" />
            <geometry>
                <cylinder length="0.4" radius="0.1" />
            </geometry>
        </visual>
        
<inertial>
            <origin rpy="0 0 0" xyz="0 0 0.2" />
            <mass value="100" />
            <inertia ixx="1.0" ixy="0.0" ixz="0.0" iyy="1.0" iyz="0.0" izz="1.0" />
        </inertial>

    </link>
    <joint name="rotation1" type="revolute">
        <parent link="base_link" />
        <child link="arm1" />
        <origin rpy="0 0 0" xyz="0 0 0.4" />
        <axis xyz="0 0 1" />
        <limit effort="1000" lower="-2.6" upper="2.6" velocity="1" />
    </joint>
    <link name="arm1">
        <collision>
            <origin rpy="0 0 0" xyz="0 -0.5 0.05" />
            <geometry>
                <box size="0.1 0.9 0.1" />
            </geometry>
        </collision>
        <visual>
            <origin rpy="0 0 0" xyz="0 -0.5 0.05" />
            <geometry>
                <box size="0.1 0.9 0.1" />
            </geometry>
        </visual>
        
<inertial>
            <origin rpy="0 0 0" xyz="0 0 0.05" />
            <mass value="50" />
            <inertia ixx="1" ixy="0.0" ixz="0.0" iyy="1" iyz="0.0" izz="1" />
        </inertial>

    </link>
    <joint name="rotation2" type="revolute">
        <parent link="arm1" />
        <child link="arm2" />
        <origin rpy="0 0 0" xyz="0 -1 0.1" />
        <axis xyz="0 0 1" />
        <limit effort="1000" lower="-3.00" upper="3.00" velocity="1" />
    </joint>
    <link name="arm2">
        <collision>
            <origin rpy="0 0 0" xyz="0 -0.4 0.05" />
            <geometry>
                <box size="0.1 0.9 0.1" />
            </geometry>
        </collision>
        <visual>
            <origin rpy="0 0 0" xyz="0 -0.4 0.05" />
            <geometry>
                <box size="0.1 0.9 0.1" />
            </geometry>
        </visual>
        
<inertial>
            <origin rpy="0 0 0" xyz="0 0 0.05" />
            <mass value="10" />
            <inertia ixx="1" ixy="0.0" ixz="0.0" iyy="1" iyz="0.0" izz="1" />
        </inertial>

    </link>
    <joint name="prismatic1" type="prismatic">
        <parent link="arm2" />
        <child link="arm3" />
        <origin rpy="0 0 0" xyz="0 -0.8 0" />
        <axis xyz="0 0 1" />
        <limit effort="100" lower="-0.05" upper="0.0" velocity="0.3" />
    </joint>
    <link name="arm3">
        <collision>
            <origin rpy="0 0 0" xyz="0 0 -0.1" />
            <geometry>
                <cylinder length="0.2" radius="0.02" />
            </geometry>
        </collision>
        <visual>
            <origin rpy="0 0 0" xyz="0 0 -0.1" />
            <geometry>
                <cylinder length="0.2" radius="0.02" />
            </geometry>
        </visual>
        
<inertial>
            <origin rpy="0 0 0" xyz="0 0 0" />
            <mass value="0.01" />
            <inertia ixx="1" ixy="0.0" ixz="0.0" iyy="1" iyz="0.0" izz="1" />
        </inertial>

    </link>
    <link name="gripper_link">
        
<inertial>
            <origin rpy="0 0 0" xyz="0 0 0" />
            <mass value="0.3" />
            <inertia ixx="0.0001" ixy="0" ixz="0" iyy="0.0002" iyz="0" izz="0.0001" />
        </inertial>

        <visual>
            <origin rpy="0 0 0" xyz="0 0 0" />
            <geometry>
                <mesh filename="package://simenv/meshes/gripper/gripper_base.dae" scale="0.5 0.5 0.5" />
            </geometry>
        </visual>
        <collision>
            <origin rpy="0 0 0" xyz="0 0 0" />
            <geometry>
                <mesh filename="package://simenv/meshes/gripper/gripper_base.dae" scale="0.5 0.5 0.5" />
            </geometry>
        </collision>
    </link>
    <link name="right_gripper_finger_link">
        
<inertial>
            <origin rpy="0 0 0" xyz="0 0 0" />
            <mass value="0.1" />
            <inertia ixx="0.002" ixy="0" ixz="0" iyy="0.0002" iyz="0" izz="0.0002" />
        </inertial>

        <visual>
            <origin rpy="0 0 0" xyz="0 0 0" />
            <geometry>
                <mesh filename="package://simenv/meshes/gripper/finger_right.dae" scale="0.5 0.5 0.5" />
            </geometry>
        </visual>
        <collision>
            <origin rpy="0 0 0" xyz="0 0 0" />
            <geometry>
                <mesh filename="package://simenv/meshes/gripper/finger_right_collision.dae" scale="0.5 0.5 0.5" />
            </geometry>
        </collision>
    </link>
    <link name="left_gripper_finger_link">
        
<inertial>
            <origin rpy="0 0 0" xyz="0 0 0" />
            <mass value="0.1" />
            <inertia ixx="0.002" ixy="0" ixz="0" iyy="0.0002" iyz="0" izz="0.0002" />
        </inertial>

        <visual>
            <origin rpy="0 0 0" xyz="0 0 0" />
            <geometry>
                <mesh filename="package://simenv/meshes/gripper/finger_left.dae" scale="0.5 0.5 0.5" />
            </geometry>
        </visual>
        <collision>
            <origin rpy="0 0 0" xyz="0 0 0" />
            <geometry>
                <mesh filename="package://simenv/meshes/gripper/finger_left_collision.dae" scale="0.5 0.5 0.5" />
            </geometry>
        </collision>
    </link>
    <joint name="right_gripper_finger_joint" type="prismatic">
        <origin rpy="0 0 0" xyz="0.078 -0.0725 0" />
        <parent link="gripper_link" />
        <child link="right_gripper_finger_link" />
        <axis xyz="0 1 0" />
        <limit effort="100" lower="-0.01" upper="0.06" velocity="0.05" />
        <dynamics damping="0.7" />
    </joint>
    <joint name="left_gripper_finger_joint" type="prismatic">
        <origin rpy="0 0 0" xyz="0.078 0.0725 0" />
        <parent link="gripper_link" />
        <child link="left_gripper_finger_link" />
        <axis xyz="0 -1 0" />
        <limit effort="100" lower="-0.01" upper="0.06" velocity="0.05" />
        <dynamics damping="0.7" />
    </joint>
    <joint name="gripper_joint" type="fixed">
        <parent link="arm3" />
        <child link="gripper_link" />
        <origin rpy="0 1.57 0" xyz="0 0 -0.2" />
        <axis xyz="0 1 0" />
    </joint>
    <gazebo reference="left_gripper_finger_link">
        <material>Gazebo/Grey</material>
        <kp>1000000.0</kp>
        <kd>1.0</kd>
        <mu1>30.0</mu1>
        <mu2>30.0</mu2>
    </gazebo>
    <gazebo reference="right_gripper_finger_link">
        <material>Gazebo/Grey</material>
        <kp>1000000.0</kp>
        <kd>1.0</kd>
        <mu1>30.0</mu1>
        <mu2>30.0</mu2>
    </gazebo>
    
<transmission name="trans_rotation1">
        <type>transmission_interface/SimpleTransmission</type>
        <joint name="rotation1">
            <hardwareInterface>hardware_interface/EffortJointInterface</hardwareInterface>
        </joint>
        <actuator name="rotation1_motor">
            <hardwareInterface>hardware_interface/EffortJointInterface</hardwareInterface>
            <mechanicalReduction>1</mechanicalReduction>
        </actuator>
    </transmission>
    <transmission name="trans_rotation2">
        <type>transmission_interface/SimpleTransmission</type>
        <joint name="rotation2">
            <hardwareInterface>hardware_interface/EffortJointInterface</hardwareInterface>
        </joint>
        <actuator name="rotation2_motor">
            <hardwareInterface>hardware_interface/EffortJointInterface</hardwareInterface>
            <mechanicalReduction>1</mechanicalReduction>
        </actuator>
    </transmission>
    <transmission name="trans_prismatic1">
        <type>transmission_interface/SimpleTransmission</type>
        <joint name="prismatic1">
            <hardwareInterface>hardware_interface/EffortJointInterface</hardwareInterface>
        </joint>
        <actuator name="prismatic1_motor">
            <hardwareInterface>hardware_interface/EffortJointInterface</hardwareInterface>
            <mechanicalReduction>1</mechanicalReduction>
        </actuator>
    </transmission>
    <transmission name="trans_right_gripper_finger_joint">
        <type>transmission_interface/SimpleTransmission</type>
        <joint name="right_gripper_finger_joint">
            <hardwareInterface>hardware_interface/EffortJointInterface</hardwareInterface>
        </joint>
        <actuator name="right_gripper_finger_joint_motor">
            <hardwareInterface>hardware_interface/EffortJointInterface</hardwareInterface>
            <mechanicalReduction>1</mechanicalReduction>
        </actuator>
    </transmission>
    <transmission name="trans_left_gripper_finger_joint">
        <type>transmission_interface/SimpleTransmission</type>
        <joint name="left_gripper_finger_joint">
            <hardwareInterface>hardware_interface/EffortJointInterface</hardwareInterface>
        </joint>
        <actuator name="left_gripper_finger_joint_motor">
            <hardwareInterface>hardware_interface/EffortJointInterface</hardwareInterface>
            <mechanicalReduction>1</mechanicalReduction>
        </actuator>
    </transmission>
    <gazebo>
        <plugin name="gazebo_ros_control" filename="libgazebo_ros_control.so">
            <robotNamespace>/</robotNamespace>
        </plugin>
    </gazebo>
</robot>
